Workbook

Sheet 使用说明与评分口径
A1: 广西电网公司 AI 高价值场景评估表 — 使用说明与评分口径
A3: 一、覆盖范围
A4: 组织层级 | B4: 省公司本部职能部门 + 直属机构（调度/交易/计量/客服/电科院/培训） + 地市供电局 + 县域新电力 + 产业公司
A5: 场景总数 | B5: 180 个工作场景，覆盖 28 个一级单位
A6: 场景颗粒度 | B6: 以“岗位日常产出物”为单位，可直接对应一次立项或一个功能模块
A8: 二、五个维度的计分规则（均为 1-5 分，分值越高越有利于 AI 落地）
A9: 维度 | B9: 权重 | C9: 5 分 | D9: 4 分 | E9: 3 分 | F9: 2 分 | G9: 1 分
A10: ① 创收 / 开支 | B10: 25% | C10: 直接创收 | D10: 直接减损/增收回 | E10: 降本增效 | F10: 风险合规避损 | G10: 纯支出型职能
A11: ② 高频 / 低频 | B11: 25% | C11: 每日/实时 | D11: 每周 | E11: 每月 | F11: 每季 | G11: 年度/偶发
A12: ③ 涉密 / 敏感 | B12: 15% | C12: 公开·低敏感 | D12: 一般内部 | E12: 商业敏感 | F12: 高敏感（客户/财务数据） | G12: 涉密（调度控制/纪检/安全）
A13: ④ 独立 / 协作 | B13: 15% | C13: 单部门可独立完成 | D13: 少量协作 | E13: 跨2-3部门协作 | F13: 跨专业＋外部单位 | G13: 需总部/跨企业协同
A14: ⑤ 技术难度 | B14: 20% | C14: 成熟技术即用 | D14: 较易实现 | E14: 中等难度 | F14: 较难 | G14: 前沿攻关
A16: 三、综合得分与优先级
A17: 综合得分公式 | B17: ①×25% ＋ ②×25% ＋ ③×15% ＋ ④×15% ＋ ⑤×20%（满分 5.00）
A18: P1 立即启动 | B18: 综合得分 ≥ 4.00 — 收益直接、频次高、数据可得、技术成熟，3 个月内可见量化结果
A19: P2 半年内推进 | B19: 3.60 ≤ 综合得分 < 4.00 — 价值明确，需一定跨部门协调或数据准备
A20: P3 储备观察 | B20: 3.20 ≤ 综合得分 < 3.60 — 具备价值但受协作面或技术成熟度制约
A21: P4 暂缓 | B21: 综合得分 < 3.20 — 涉密度高、频次低或南网总部已统建，重复投入回报有限
A23: 四、使用提示
A24: 读表顺序 | B24: 先看“AI高价值场景排序”前 40 行，再用“分单位价值分布”判断从哪个单位切入
A25: 得分为相对量 | B25: 五个维度的分值用于横向比较场景优先级，不代表绝对收益金额
A26: 需现场校准的项 | B26: 涉密等级、数据可得性与协作面以客户实际管理口径为准，建议在调研阶段逐项确认
A27: 评分依据 | B27: 组织架构与岗位设置依据南方电网省级电网公司通行设置及广西电网公开信息整理；场景频次与收益属性依据电网业务通行实践判断

Sheet AI高价值场景排序
A1: 排名 | B1: 一级单位 | C1: 科室 / 岗位群 | D1: 典型岗位 | E1: 工作场景 | F1: ①收益属性 | G1: ①得分 | H1: ②发生频次 | I1: ②得分 | J1: ③敏感等级 | K1: ③得分 | L1: ④协作程度 | M1: ④得分 | N1: ⑤技术难度 | O1: ⑤得分 | P1: 综合得分 | Q1: 优先级 | R1: 建议 AI 技术路线 | S1: 落地备注
A2: 1 | B2: 广西电动汽车服务公司 | C2: 运营 | D2: 站点运营岗 | E2: 充电站运营分析与动态价格策略 | F2: 直接创收 | G2: 5 | H2: 每日/实时 | I2: 5 | J2: 商业敏感 | K2: 3 | L2: 少量协作 | M2: 4 | N2: 较易实现 | O2: 4 | P2: =ROUND(G2*0.25+I2*0.25+K2*0.15+M2*0.15+O2*0.2,2) -> 4.35 | Q2: =IF(P2>=4,"P1 立即启动",IF(P2>=3.6,"P2 半年内推进",IF(P2>=3.2,"P3 储备观察","P4 暂缓"))) -> P1 立即启动 | R2: 需求预测＋动态定价 | S2: 高频高收益，数据自有
A3: 2 | B3: 市场营销部 | C3: 线损管理 | D3: 线损专责 | E3: 台区线损分析与治理定位 | F3: 直接创收 | G3: 5 | H3: 每日/实时 | I3: 5 | J3: 商业敏感 | K3: 3 | L3: 少量协作 | M3: 4 | N3: 中等难度 | O3: 3 | P3: =ROUND(G3*0.25+I3*0.25+K3*0.15+M3*0.15+O3*0.2,2) -> 4.15 | Q3: =IF(P3>=4,"P1 立即启动",IF(P3>=3.6,"P2 半年内推进",IF(P3>=3.2,"P3 储备观察","P4 暂缓"))) -> P1 立即启动 | R3: 电气拓扑校验＋异常归因模型 | S3: 线损率是硬考核指标，收益直接落账
A4: 3 | B4: 广西新电力投资集团（40家县企） | C4: 线损管理 | D4: 农网线损专责 | E4: 农网台区线损治理与窃电定位 | F4: 直接创收 | G4: 5 | H4: 每日/实时 | I4: 5 | J4: 商业敏感 | K4: 3 | L4: 少量协作 | M4: 4 | N4: 中等难度 | O4: 3 | P4: =ROUND(G4*0.25+I4*0.25+K4*0.15+M4*0.15+O4*0.2,2) -> 4.15 | Q4: =IF(P4>=4,"P1 立即启动",IF(P4>=3.6,"P2 半年内推进",IF(P4>=3.2,"P3 储备观察","P4 暂缓"))) -> P1 立即启动 | R4: 台区拓扑校验＋异常用户定位 | S4: 农网线损率高于城网，收益空间最大
A5: 4 | B5: 地市供电局（14个） | C5: 供电所 | D5: 台区经理 | E5: 台区片区服务、走访与用电潜力挖掘 | F5: 直接减损/增收回 | G5: 4 | H5: 每日/实时 | I5: 5 | J5: 商业敏感 | K5: 3 | L5: 少量协作 | M5: 4 | N5: 较易实现 | O5: 4 | P5: =ROUND(G5*0.25+I5*0.25+K5*0.15+M5*0.15+O5*0.2,2) -> 4.1 | Q5: =IF(P5>=4,"P1 立即启动",IF(P5>=3.6,"P2 半年内推进",IF(P5>=3.2,"P3 储备观察","P4 暂缓"))) -> P1 立即启动 | R5: 客户画像＋走访任务推荐 | S5: 一线创收触点
A6: 5 | B6: 地市供电局（14个） | C6: 客户服务 | D6: 业扩勘查员 | E6: 用电报装现场勘查与方案初判 | F6: 直接减损/增收回 | G6: 4 | H6: 每日/实时 | I6: 5 | J6: 商业敏感 | K6: 3 | L6: 少量协作 | M6: 4 | N6: 较易实现 | O6: 4 | P6: =ROUND(G6*0.25+I6*0.25+K6*0.15+M6*0.15+O6*0.2,2) -> 4.1 | Q6: =IF(P6>=4,"P1 立即启动",IF(P6>=3.6,"P2 半年内推进",IF(P6>=3.2,"P3 储备观察","P4 暂缓"))) -> P1 立即启动 | R6: 移动端影像识别＋方案推荐 | S6: 办电时长是营商环境考核项
A7: 6 | B7: 市场营销部 | C7: 业扩报装 | D7: 业扩报装专责 | E7: 业扩报装受理、流程流转与超期预警 | F7: 直接减损/增收回 | G7: 4 | H7: 每日/实时 | I7: 5 | J7: 商业敏感 | K7: 3 | L7: 少量协作 | M7: 4 | N7: 较易实现 | O7: 4 | P7: =ROUND(G7*0.25+I7*0.25+K7*0.15+M7*0.15+O7*0.2,2) -> 4.1 | Q7: =IF(P7>=4,"P1 立即启动",IF(P7>=3.6,"P2 半年内推进",IF(P7>=3.2,"P3 储备观察","P4 暂缓"))) -> P1 立即启动 | R7: 流程智能体＋OCR资料核验 | S7: 高频刚需，数据在管理信息大区
A8: 7 | B8: 市场营销部 | C8: 客户经理 | D8: 大客户经理 | E8: 重点客户走访与增供扩销机会挖掘 | F8: 直接创收 | G8: 5 | H8: 每周 | I8: 4 | J8: 商业敏感 | K8: 3 | L8: 少量协作 | M8: 4 | N8: 较易实现 | O8: 4 | P8: =ROUND(G8*0.25+I8*0.25+K8*0.15+M8*0.15+O8*0.2,2) -> 4.1 | Q8: =IF(P8>=4,"P1 立即启动",IF(P8>=3.6,"P2 半年内推进",IF(P8>=3.2,"P3 储备观察","P4 暂缓"))) -> P1 立即启动 | R8: 行业用电画像＋潜力客户推荐 | S8: 直接创收，售电量是核心考核
A9: 8 | B9: 生产技术部 | C9: 输电管理 | D9: 通道管理专责 | E9: 线路通道外破隐患识别（施工机械/树障） | F9: 直接减损/增收回 | G9: 4 | H9: 每日/实时 | I9: 5 | J9: 商业敏感 | K9: 3 | L9: 少量协作 | M9: 4 | N9: 较易实现 | O9: 4 | P9: =ROUND(G9*0.25+I9*0.25+K9*0.15+M9*0.15+O9*0.2,2) -> 4.1 | Q9: =IF(P9>=4,"P1 立即启动",IF(P9>=3.6,"P2 半年内推进",IF(P9>=3.2,"P3 储备观察","P4 暂缓"))) -> P1 立即启动 | R9: 视觉目标检测＋边缘告警 | S9: 外破是跳闸主因之一，防损收益明确
A10: 9 | B10: 计量中心 | C10: 采集运维 | D10: 采集运维专责 | E10: 用电信息采集成功率提升与异常处理 | F10: 直接减损/增收回 | G10: 4 | H10: 每日/实时 | I10: 5 | J10: 商业敏感 | K10: 3 | L10: 少量协作 | M10: 4 | N10: 较易实现 | O10: 4 | P10: =ROUND(G10*0.25+I10*0.25+K10*0.15+M10*0.15+O10*0.2,2) -> 4.1 | Q10: =IF(P10>=4,"P1 立即启动",IF(P10>=3.6,"P2 半年内推进",IF(P10>=3.2,"P3 储备观察","P4 暂缓"))) -> P1 立即启动 | R10: 通信异常诊断＋根因定位 | S10: 采集率直接决定线损与电费准确性
A11: 10 | B11: 人力资源部 | C11: 综合管理 | D11: 人资综合专责 | E11: 人资制度与政策智能问答 | F11: 风险合规避损 | G11: 2 | H11: 每日/实时 | I11: 5 | J11: 商业敏感 | K11: 3 | L11: 单部门可独立完成 | M11: 5 | N11: 成熟技术即用 | O11: 5 | P11: =ROUND(G11*0.25+I11*0.25+K11*0.15+M11*0.15+O11*0.2,2) -> 3.95 | Q11: =IF(P11>=4,"P1 立即启动",IF(P11>=3.6,"P2 半年内推进",IF(P11>=3.2,"P3 储备观察","P4 暂缓"))) -> P2 半年内推进 | R11: RAG知识问答 | S11: 广西电网已建成，问答准确率95%，勿重复投入
A12: 11 | B12: 市场营销部 | C12: 电价电费 | D12: 电费核算专责 | E12: 电费核算差错稽核与电量异常识别 | F12: 直接减损/增收回 | G12: 4 | H12: 每日/实时 | I12: 5 | J12: 高敏感（客户/财务数据） | K12: 2 | L12: 少量协作 | M12: 4 | N12: 较易实现 | O12: 4 | P12: =ROUND(G12*0.25+I12*0.25+K12*0.15+M12*0.15+O12*0.2,2) -> 3.95 | Q12: =IF(P12>=4,"P1 立即启动",IF(P12>=3.6,"P2 半年内推进",IF(P12>=3.2,"P3 储备观察","P4 暂缓"))) -> P2 半年内推进 | R12: 异常检测＋规则比对 | S12: 涉及客户敏感数据，需脱敏
A13: 12 | B13: 市场营销部 | C13: 电费回收 | D13: 电费回收专责 | E13: 客户欠费风险预警与差异化催收 | F13: 直接创收 | G13: 5 | H13: 每周 | I13: 4 | J13: 高敏感（客户/财务数据） | K13: 2 | L13: 少量协作 | M13: 4 | N13: 较易实现 | O13: 4 | P13: =ROUND(G13*0.25+I13*0.25+K13*0.15+M13*0.15+O13*0.2,2) -> 3.95 | Q13: =IF(P13>=4,"P1 立即启动",IF(P13>=3.6,"P2 半年内推进",IF(P13>=3.2,"P3 储备观察","P4 暂缓"))) -> P2 半年内推进 | R13: 信用评分＋违约概率预测 | S13: 直接改善现金流
... A181: 180 | B181: 电力调度控制中心（省调） | C181: 调度运行 | D181: 值班调度员 | E181: 电网故障处置与事故预案调用 | F181: 风险合规避损 | G181: 2 | H181: 每季 | I181: 2 | J181: 涉密（调度控制/纪检/安全） | K181: 1 | L181: 需总部/跨企业协同 | M181: 1 | N181: 前沿攻关 | O181: 1 | P181: =ROUND(G181*0.25+I181*0.25+K181*0.15+M181*0.15+O181*0.2,2) -> 1.5 | Q181: =IF(P181>=4,"P1 立即启动",IF(P181>=3.6,"P2 半年内推进",IF(P181>=3.2,"P3 储备观察","P4 暂缓"))) -> P4 暂缓 | R181: 知识图谱＋案例推理 | S181: 事故处置责任重，AI仅可辅助

Sheet Top40 快赢清单
A1: Top 40 快赢场景（按综合得分自动取自主表前 40 行）
A2: 排名 | B2: 一级单位 | C2: 工作场景 | D2: 收益属性 | E2: 发生频次 | F2: 综合得分 | G2: 优先级 | H2: 建议 AI 技术路线
A3: =AI高价值场景排序!A2 -> 1 | B3: =AI高价值场景排序!B2 -> 广西电动汽车服务公司 | C3: =AI高价值场景排序!E2 -> 充电站运营分析与动态价格策略 | D3: =AI高价值场景排序!F2 -> 直接创收 | E3: =AI高价值场景排序!H2 -> 每日/实时 | F3: =AI高价值场景排序!P2 -> 4.35 | G3: =AI高价值场景排序!Q2 -> P1 立即启动 | H3: =AI高价值场景排序!R2 -> 需求预测＋动态定价
A4: =AI高价值场景排序!A3 -> 2 | B4: =AI高价值场景排序!B3 -> 市场营销部 | C4: =AI高价值场景排序!E3 -> 台区线损分析与治理定位 | D4: =AI高价值场景排序!F3 -> 直接创收 | E4: =AI高价值场景排序!H3 -> 每日/实时 | F4: =AI高价值场景排序!P3 -> 4.15 | G4: =AI高价值场景排序!Q3 -> P1 立即启动 | H4: =AI高价值场景排序!R3 -> 电气拓扑校验＋异常归因模型
A5: =AI高价值场景排序!A4 -> 3 | B5: =AI高价值场景排序!B4 -> 广西新电力投资集团（40家县企） | C5: =AI高价值场景排序!E4 -> 农网台区线损治理与窃电定位 | D5: =AI高价值场景排序!F4 -> 直接创收 | E5: =AI高价值场景排序!H4 -> 每日/实时 | F5: =AI高价值场景排序!P4 -> 4.15 | G5: =AI高价值场景排序!Q4 -> P1 立即启动 | H5: =AI高价值场景排序!R4 -> 台区拓扑校验＋异常用户定位
A6: =AI高价值场景排序!A5 -> 4 | B6: =AI高价值场景排序!B5 -> 地市供电局（14个） | C6: =AI高价值场景排序!E5 -> 台区片区服务、走访与用电潜力挖掘 | D6: =AI高价值场景排序!F5 -> 直接减损/增收回 | E6: =AI高价值场景排序!H5 -> 每日/实时 | F6: =AI高价值场景排序!P5 -> 4.1 | G6: =AI高价值场景排序!Q5 -> P1 立即启动 | H6: =AI高价值场景排序!R5 -> 客户画像＋走访任务推荐
A7: =AI高价值场景排序!A6 -> 5 | B7: =AI高价值场景排序!B6 -> 地市供电局（14个） | C7: =AI高价值场景排序!E6 -> 用电报装现场勘查与方案初判 | D7: =AI高价值场景排序!F6 -> 直接减损/增收回 | E7: =AI高价值场景排序!H6 -> 每日/实时 | F7: =AI高价值场景排序!P6 -> 4.1 | G7: =AI高价值场景排序!Q6 -> P1 立即启动 | H7: =AI高价值场景排序!R6 -> 移动端影像识别＋方案推荐
A8: =AI高价值场景排序!A7 -> 6 | B8: =AI高价值场景排序!B7 -> 市场营销部 | C8: =AI高价值场景排序!E7 -> 业扩报装受理、流程流转与超期预警 | D8: =AI高价值场景排序!F7 -> 直接减损/增收回 | E8: =AI高价值场景排序!H7 -> 每日/实时 | F8: =AI高价值场景排序!P7 -> 4.1 | G8: =AI高价值场景排序!Q7 -> P1 立即启动 | H8: =AI高价值场景排序!R7 -> 流程智能体＋OCR资料核验
A9: =AI高价值场景排序!A8 -> 7 | B9: =AI高价值场景排序!B8 -> 市场营销部 | C9: =AI高价值场景排序!E8 -> 重点客户走访与增供扩销机会挖掘 | D9: =AI高价值场景排序!F8 -> 直接创收 | E9: =AI高价值场景排序!H8 -> 每周 | F9: =AI高价值场景排序!P8 -> 4.1 | G9: =AI高价值场景排序!Q8 -> P1 立即启动 | H9: =AI高价值场景排序!R8 -> 行业用电画像＋潜力客户推荐
A10: =AI高价值场景排序!A9 -> 8 | B10: =AI高价值场景排序!B9 -> 生产技术部 | C10: =AI高价值场景排序!E9 -> 线路通道外破隐患识别（施工机械/树障） | D10: =AI高价值场景排序!F9 -> 直接减损/增收回 | E10: =AI高价值场景排序!H9 -> 每日/实时 | F10: =AI高价值场景排序!P9 -> 4.1 | G10: =AI高价值场景排序!Q9 -> P1 立即启动 | H10: =AI高价值场景排序!R9 -> 视觉目标检测＋边缘告警
A11: =AI高价值场景排序!A10 -> 9 | B11: =AI高价值场景排序!B10 -> 计量中心 | C11: =AI高价值场景排序!E10 -> 用电信息采集成功率提升与异常处理 | D11: =AI高价值场景排序!F10 -> 直接减损/增收回 | E11: =AI高价值场景排序!H10 -> 每日/实时 | F11: =AI高价值场景排序!P10 -> 4.1 | G11: =AI高价值场景排序!Q10 -> P1 立即启动 | H11: =AI高价值场景排序!R10 -> 通信异常诊断＋根因定位
A12: =AI高价值场景排序!A11 -> 10 | B12: =AI高价值场景排序!B11 -> 人力资源部 | C12: =AI高价值场景排序!E11 -> 人资制度与政策智能问答 | D12: =AI高价值场景排序!F11 -> 风险合规避损 | E12: =AI高价值场景排序!H11 -> 每日/实时 | F12: =AI高价值场景排序!P11 -> 3.95 | G12: =AI高价值场景排序!Q11 -> P2 半年内推进 | H12: =AI高价值场景排序!R11 -> RAG知识问答
A13: =AI高价值场景排序!A12 -> 11 | B13: =AI高价值场景排序!B12 -> 市场营销部 | C13: =AI高价值场景排序!E12 -> 电费核算差错稽核与电量异常识别 | D13: =AI高价值场景排序!F12 -> 直接减损/增收回 | E13: =AI高价值场景排序!H12 -> 每日/实时 | F13: =AI高价值场景排序!P12 -> 3.95 | G13: =AI高价值场景排序!Q12 -> P2 半年内推进 | H13: =AI高价值场景排序!R12 -> 异常检测＋规则比对
A14: =AI高价值场景排序!A13 -> 12 | B14: =AI高价值场景排序!B13 -> 市场营销部 | C14: =AI高价值场景排序!E13 -> 客户欠费风险预警与差异化催收 | D14: =AI高价值场景排序!F13 -> 直接创收 | E14: =AI高价值场景排序!H13 -> 每周 | F14: =AI高价值场景排序!P13 -> 3.95 | G14: =AI高价值场景排序!Q13 -> P2 半年内推进 | H14: =AI高价值场景排序!R13 -> 信用评分＋违约概率预测
... A42: =AI高价值场景排序!A41 -> 40 | B42: =AI高价值场景排序!B41 -> 客户服务中心（95598） | C42: =AI高价值场景排序!E41 -> 智能语音客服与用户意图识别 | D42: =AI高价值场景排序!F41 -> 风险合规避损 | E42: =AI高价值场景排序!H41 -> 每日/实时 | F42: =AI高价值场景排序!P41 -> 3.6 | G42: =AI高价值场景排序!Q41 -> P2 半年内推进 | H42: =AI高价值场景排序!R41 -> 语音识别＋意图理解＋知识问答

Sheet 分单位价值分布
A1: 分单位场景数量与平均价值分布
A2: 一级单位 | B2: 场景数 | C2: 平均综合得分 | D2: P1 场景数 | E2: P2 场景数 | F2: 最高分场景
A3: 广西电动汽车服务公司 | B3: =COUNTIF(AI高价值场景排序!$B$2:$B$181,$A3) -> 3 | C3: =ROUND(AVERAGEIF(AI高价值场景排序!$B$2:$B$181,$A3,AI高价值场景排序!$P$2:$P$181),2) -> 3.82 | D3: =COUNTIFS(AI高价值场景排序!$B$2:$B$181,$A3,AI高价值场景排序!$Q$2:$Q$181,"P1 立即启动") -> 1 | E3: =COUNTIFS(AI高价值场景排序!$B$2:$B$181,$A3,AI高价值场景排序!$Q$2:$Q$181,"P2 半年内推进") -> 1 | F3: 充电站运营分析与动态价格策略
A4: 广西新电力投资集团（40家县企） | B4: =COUNTIF(AI高价值场景排序!$B$2:$B$181,$A4) -> 3 | C4: =ROUND(AVERAGEIF(AI高价值场景排序!$B$2:$B$181,$A4,AI高价值场景排序!$P$2:$P$181),2) -> 3.78 | D4: =COUNTIFS(AI高价值场景排序!$B$2:$B$181,$A4,AI高价值场景排序!$Q$2:$Q$181,"P1 立即启动") -> 1 | E4: =COUNTIFS(AI高价值场景排序!$B$2:$B$181,$A4,AI高价值场景排序!$Q$2:$Q$181,"P2 半年内推进") -> 1 | F4: 农网台区线损治理与窃电定位
A5: 党建工作部（宣传） | B5: =COUNTIF(AI高价值场景排序!$B$2:$B$181,$A5) -> 1 | C5: =ROUND(AVERAGEIF(AI高价值场景排序!$B$2:$B$181,$A5,AI高价值场景排序!$P$2:$P$181),2) -> 3.7 | D5: =COUNTIFS(AI高价值场景排序!$B$2:$B$181,$A5,AI高价值场景排序!$Q$2:$Q$181,"P1 立即启动") -> 0 | E5: =COUNTIFS(AI高价值场景排序!$B$2:$B$181,$A5,AI高价值场景排序!$Q$2:$Q$181,"P2 半年内推进") -> 1 | F5: 新闻稿件、外宣素材与融媒体内容生产
A6: 广西送变电建设公司 | B6: =COUNTIF(AI高价值场景排序!$B$2:$B$181,$A6) -> 3 | C6: =ROUND(AVERAGEIF(AI高价值场景排序!$B$2:$B$181,$A6,AI高价值场景排序!$P$2:$P$181),2) -> 3.68 | D6: =COUNTIFS(AI高价值场景排序!$B$2:$B$181,$A6,AI高价值场景排序!$Q$2:$Q$181,"P1 立即启动") -> 0 | E6: =COUNTIFS(AI高价值场景排序!$B$2:$B$181,$A6,AI高价值场景排序!$Q$2:$Q$181,"P2 半年内推进") -> 3 | F6: 施工机械、人员与工序智能调度
A7: 地市供电局（14个） | B7: =COUNTIF(AI高价值场景排序!$B$2:$B$181,$A7) -> 8 | C7: =ROUND(AVERAGEIF(AI高价值场景排序!$B$2:$B$181,$A7,AI高价值场景排序!$P$2:$P$181),2) -> 3.68 | D7: =COUNTIFS(AI高价值场景排序!$B$2:$B$181,$A7,AI高价值场景排序!$Q$2:$Q$181,"P1 立即启动") -> 2 | E7: =COUNTIFS(AI高价值场景排序!$B$2:$B$181,$A7,AI高价值场景排序!$Q$2:$Q$181,"P2 半年内推进") -> 3 | F7: 台区片区服务、走访与用电潜力挖掘
A8: 广西电网能源科技公司 | B8: =COUNTIF(AI高价值场景排序!$B$2:$B$181,$A8) -> 4 | C8: =ROUND(AVERAGEIF(AI高价值场景排序!$B$2:$B$181,$A8,AI高价值场景排序!$P$2:$P$181),2) -> 3.65 | D8: =COUNTIFS(AI高价值场景排序!$B$2:$B$181,$A8,AI高价值场景排序!$Q$2:$Q$181,"P1 立即启动") -> 0 | E8: =COUNTIFS(AI高价值场景排序!$B$2:$B$181,$A8,AI高价值场景排序!$Q$2:$Q$181,"P2 半年内推进") -> 3 | F8: 综合能源项目机会识别与收益测算
A9: 市场营销部 | B9: =COUNTIF(AI高价值场景排序!$B$2:$B$181,$A9) -> 20 | C9: =ROUND(AVERAGEIF(AI高价值场景排序!$B$2:$B$181,$A9,AI高价值场景排序!$P$2:$P$181),2) -> 3.62 | D9: =COUNTIFS(AI高价值场景排序!$B$2:$B$181,$A9,AI高价值场景排序!$Q$2:$Q$181,"P1 立即启动") -> 3 | E9: =COUNTIFS(AI高价值场景排序!$B$2:$B$181,$A9,AI高价值场景排序!$Q$2:$Q$181,"P2 半年内推进") -> 10 | F9: 台区线损分析与治理定位
A10: 计量中心 | B10: =COUNTIF(AI高价值场景排序!$B$2:$B$181,$A10) -> 4 | C10: =ROUND(AVERAGEIF(AI高价值场景排序!$B$2:$B$181,$A10,AI高价值场景排序!$P$2:$P$181),2) -> 3.53 | D10: =COUNTIFS(AI高价值场景排序!$B$2:$B$181,$A10,AI高价值场景排序!$Q$2:$Q$181,"P1 立即启动") -> 1 | E10: =COUNTIFS(AI高价值场景排序!$B$2:$B$181,$A10,AI高价值场景排序!$Q$2:$Q$181,"P2 半年内推进") -> 0 | F10: 用电信息采集成功率提升与异常处理
A11: 客户服务中心（95598） | B11: =COUNTIF(AI高价值场景排序!$B$2:$B$181,$A11) -> 3 | C11: =ROUND(AVERAGEIF(AI高价值场景排序!$B$2:$B$181,$A11,AI高价值场景排序!$P$2:$P$181),2) -> 3.52 | D11: =COUNTIFS(AI高价值场景排序!$B$2:$B$181,$A11,AI高价值场景排序!$Q$2:$Q$181,"P1 立即启动") -> 0 | E11: =COUNTIFS(AI高价值场景排序!$B$2:$B$181,$A11,AI高价值场景排序!$Q$2:$Q$181,"P2 半年内推进") -> 2 | F11: 智能语音客服与用户意图识别
A12: 广西电力交易中心 | B12: =COUNTIF(AI高价值场景排序!$B$2:$B$181,$A12) -> 8 | C12: =ROUND(AVERAGEIF(AI高价值场景排序!$B$2:$B$181,$A12,AI高价值场景排序!$P$2:$P$181),2) -> 3.43 | D12: =COUNTIFS(AI高价值场景排序!$B$2:$B$181,$A12,AI高价值场景排序!$Q$2:$Q$181,"P1 立即启动") -> 0 | E12: =COUNTIFS(AI高价值场景排序!$B$2:$B$181,$A12,AI高价值场景排序!$Q$2:$Q$181,"P2 半年内推进") -> 3 | F12: 绿电与绿证交易组织及跨区撮合
A13: 生产技术部 | B13: =COUNTIF(AI高价值场景排序!$B$2:$B$181,$A13) -> 15 | C13: =ROUND(AVERAGEIF(AI高价值场景排序!$B$2:$B$181,$A13,AI高价值场景排序!$P$2:$P$181),2) -> 3.39 | D13: =COUNTIFS(AI高价值场景排序!$B$2:$B$181,$A13,AI高价值场景排序!$Q$2:$Q$181,"P1 立即启动") -> 1 | E13: =COUNTIFS(AI高价值场景排序!$B$2:$B$181,$A13,AI高价值场景排序!$Q$2:$Q$181,"P2 半年内推进") -> 5 | F13: 线路通道外破隐患识别（施工机械/树障）
A14: 物资部（供应链管理） | B14: =COUNTIF(AI高价值场景排序!$B$2:$B$181,$A14) -> 10 | C14: =ROUND(AVERAGEIF(AI高价值场景排序!$B$2:$B$181,$A14,AI高价值场景排序!$P$2:$P$181),2) -> 3.31 | D14: =COUNTIFS(AI高价值场景排序!$B$2:$B$181,$A14,AI高价值场景排序!$Q$2:$Q$181,"P1 立即启动") -> 0 | E14: =COUNTIFS(AI高价值场景排序!$B$2:$B$181,$A14,AI高价值场景排序!$Q$2:$Q$181,"P2 半年内推进") -> 1 | F14: 库存优化、呆滞物资调剂与配送计划
... A30: 纪检监察组 | B30: =COUNTIF(AI高价值场景排序!$B$2:$B$181,$A30) -> 3 | C30: =ROUND(AVERAGEIF(AI高价值场景排序!$B$2:$B$181,$A30,AI高价值场景排序!$P$2:$P$181),2) -> 1.88 | D30: =COUNTIFS(AI高价值场景排序!$B$2:$B$181,$A30,AI高价值场景排序!$Q$2:$Q$181,"P1 立即启动") -> 0 | E30: =COUNTIFS(AI高价值场景排序!$B$2:$B$181,$A30,AI高价值场景排序!$Q$2:$Q$181,"P2 半年内推进") -> 0 | F30: 重点领域廉洁风险点扫描与预警
A31: 合计 | B31: =SUM(B3:B30) -> 180 | C31: =ROUND(AVERAGE(AI高价值场景排序!P2:P181),2) -> 3.23 | D31: =SUM(D3:D30) -> 9 | E31: =SUM(E3:E30) -> 37

Sheet 组织架构与岗位全景
A1: 广西电网公司组织架构、科室与岗位全景
A2: 层级 | B2: 一级单位 | C2: 科室 / 岗位群 | D2: 典型岗位 | E2: 该岗位覆盖场景数
A3: 一、省公司本部职能部门 | B3: 人力资源部 | C3: 员工服务 | D3: 员工服务岗 | E3: 1
A4: 一、省公司本部职能部门 | C4: 培训开发 | D4: 培训专责 | E4: 1
A5: 一、省公司本部职能部门 | C5: 干部管理 | D5: 干部管理专责 | E5: 1
A6: 一、省公司本部职能部门 | C6: 招聘配置 | D6: 招聘专责 | E6: 1
A7: 一、省公司本部职能部门 | C7: 用工管理 | D7: 用工专责 | E7: 1
A8: 一、省公司本部职能部门 | C8: 组织管理 | D8: 定员定编专责 | E8: 1
A9: 一、省公司本部职能部门 | C9: 综合管理 | D9: 人资综合专责 | E9: 1
A10: 一、省公司本部职能部门 | C10: 薪酬绩效 | D10: 绩效专责 | E10: 1
A11: 一、省公司本部职能部门 | B11: 党建工作部 | C11: 组织管理 | D11: 党务专责 | E11: 1
A12: 一、省公司本部职能部门 | B12: 党建工作部（宣传） | C12: 新闻宣传 | D12: 宣传专责 | E12: 1
A13: 一、省公司本部职能部门 | B13: 办公室 | C13: 会务 | D13: 会务管理岗 | E13: 1
A14: 一、省公司本部职能部门 | C14: 政企协调 | D14: 政企关系专责 | E14: 1
A15: 一、省公司本部职能部门 | C15: 文秘 | D15: 公文处理岗 | E15: 1
A16: 一、省公司本部职能部门 | C16: 档案 | D16: 档案管理岗 | E16: 1
A17: 一、省公司本部职能部门 | C17: 督查督办 | D17: 督办专责 | E17: 1
A18: 一、省公司本部职能部门 | B18: 基建部 | C18: 工程管理 | D18: 工程管理专责 | E18: 1
A19: 一、省公司本部职能部门 | C19: 工程管理 | D19: 资料管理岗 | E19: 1
A20: 一、省公司本部职能部门 | C20: 工程管理 | D20: 变更签证专责 | E20: 1
A21: 一、省公司本部职能部门 | C21: 征地协调 | D21: 征拆协调专责 | E21: 1
A22: 一、省公司本部职能部门 | C22: 物资协同 | D22: 工程物资专责 | E22: 1
A23: 一、省公司本部职能部门 | C23: 线路设计管理 | D23: 设计管理专责 | E23: 1
A24: 一、省公司本部职能部门 | C24: 质量安全 | D24: 质量安全专责 | E24: 1
A25: 一、省公司本部职能部门 | C25: 造价管理 | D25: 造价专责 | E25: 1
A26: 一、省公司本部职能部门 | C26: 项目前期 | D26: 前期专责 | E26: 1
A27: 一、省公司本部职能部门 | C27: 项目前期 | D27: 站址规划专责 | E27: 1
A28: 一、省公司本部职能部门 | B28: 安全监管部 | C28: 事故调查 | D28: 事故调查专责 | E28: 1
A29: 一、省公司本部职能部门 | C29: 安全培训 | D29: 安全培训专责 | E29: 1
A30: 一、省公司本部职能部门 | C30: 安全监督 | D30: 安监专责 | E30: 1
A31: 一、省公司本部职能部门 | C31: 应急管理 | D31: 应急专责 | E31: 1
A32: 一、省公司本部职能部门 | C32: 承包商管理 | D32: 外包管理专责 | E32: 1
A33: 一、省公司本部职能部门 | C33: 现场管控 | D33: 作业监护专责 | E33: 1
A34: 一、省公司本部职能部门 | C34: 隐患管理 | D34: 隐患排查专责 | E34: 1
A35: 一、省公司本部职能部门 | B35: 审计部 | C35: 内部审计 | D35: 审计专责 | E35: 1
A36: 一、省公司本部职能部门 | C36: 工程审计 | D36: 工程审计专责 | E36: 1
A37: 一、省公司本部职能部门 | C37: 整改跟踪 | D37: 审计整改岗 | E37: 1
A38: 一、省公司本部职能部门 | C38: 经责审计 | D38: 经责审计岗 | E38: 1
A39: 一、省公司本部职能部门 | B39: 工会 | C39: 职工服务 | D39: 工会干事 | E39: 1
A40: 一、省公司本部职能部门 | B40: 市场营销部 | C40: 业扩报装 | D40: 业扩报装专责 | E40: 1
...
